<?xml version="1.0" encoding="UTF-8"?>
<!-- Generated by org.testng.reporters.JUnitXMLReporter -->
<testsuite hostname="P3A-HQHRXJ2" ignored="0" name="Test" tests="8" failures="4" timestamp="23 Sep 2019 04:17:06 GMT" time="0.122" errors="0">
  <testcase name="test1" time="0.018" classname="testngFeatures.DemoAssertion1">
    <failure type="java.lang.AssertionError" message="Does not match expected [Hi] but found [Hello]">
      <![CDATA[java.lang.AssertionError: Does not match expected [Hi] but found [Hello]
at testngFeatures.DemoAssertion1.test1(DemoAssertion1.java:15)
at java.util.concurrent.ThreadPoolExecutor.runWorker(Unknown Source)
at java.util.concurrent.ThreadPoolExecutor$Worker.run(Unknown Source)
at java.lang.Thread.run(Unknown Source)
... Removed 15 stack frames]]>
    </failure>
  </testcase> <!-- test1 -->
  <testcase name="f" time="0.021" classname="testngFeatures.DemoSoftAssert">
    <failure type="java.lang.AssertionError" message="The following asserts failed:
	expected [12] but found [10],
	eroor MSG expected [true] but found [false]">
      <![CDATA[java.lang.AssertionError: The following asserts failed:
expected [12] but found [10],
eroor MSG expected [true] but found [false]
at testngFeatures.DemoSoftAssert.f(DemoSoftAssert.java:16)
at java.util.concurrent.ThreadPoolExecutor.runWorker(Unknown Source)
at java.util.concurrent.ThreadPoolExecutor$Worker.run(Unknown Source)
at java.lang.Thread.run(Unknown Source)
... Removed 11 stack frames]]>
    </failure>
  </testcase> <!-- f -->
  <testcase name="test2" time="0.004" classname="testngFeatures.DemoAssertion1"/>
  <testcase name="test3" time="0.003" classname="testngFeatures.DemoAssertion1"/>
  <testcase name="test4" time="0.003" classname="testngFeatures.DemoAssertion1"/>
  <testcase name="test5" time="0.003" classname="testngFeatures.DemoAssertion1"/>
  <testcase name="test6" time="0.007" classname="testngFeatures.DemoAssertion1">
    <failure type="java.lang.AssertionError" message="intentionally failing the test">
      <![CDATA[java.lang.AssertionError: intentionally failing the test
at testngFeatures.DemoAssertion1.test6(DemoAssertion1.java:58)
at java.util.concurrent.ThreadPoolExecutor.runWorker(Unknown Source)
at java.util.concurrent.ThreadPoolExecutor$Worker.run(Unknown Source)
at java.lang.Thread.run(Unknown Source)
... Removed 11 stack frames]]>
    </failure>
  </testcase> <!-- test6 -->
  <testcase name="test7" time="0.003" classname="testngFeatures.DemoAssertion1">
    <failure type="java.lang.AssertionError" message="intentionally failing the test">
      <![CDATA[java.lang.AssertionError: intentionally failing the test
at testngFeatures.DemoAssertion1.test7(DemoAssertion1.java:68)
at java.util.concurrent.ThreadPoolExecutor.runWorker(Unknown Source)
at java.util.concurrent.ThreadPoolExecutor$Worker.run(Unknown Source)
at java.lang.Thread.run(Unknown Source)
... Removed 11 stack frames]]>
    </failure>
  </testcase> <!-- test7 -->
</testsuite> <!-- Test -->
